Traceback (most recent call last):
  File "/Library/Frameworks/Python.framework/Versions/3.7/lib/python3.7/site-packages/urllib3/connection.py", line 157, in _new_conn
    (self._dns_host, self.port), self.timeout, **extra_kw
  File "/Library/Frameworks/Python.framework/Versions/3.7/lib/python3.7/site-packages/urllib3/util/connection.py", line 61, in create_connection
    for res in socket.getaddrinfo(host, port, family, socket.SOCK_STREAM):
  File "/Library/Frameworks/Python.framework/Versions/3.7/lib/python3.7/socket.py", line 748, in getaddrinfo
    for res in _socket.getaddrinfo(host, port, family, type, proto, flags):
socket.gaierror: [Errno 8] nodename nor servname provided, or not known

During handling of the above exception, another exception occurred:

Traceback (most recent call last):
  File "/Library/Frameworks/Python.framework/Versions/3.7/lib/python3.7/site-packages/urllib3/connectionpool.py", line 672, in urlopen
    chunked=chunked,
  File "/Library/Frameworks/Python.framework/Versions/3.7/lib/python3.7/site-packages/urllib3/connectionpool.py", line 376, in _make_request
    self._validate_conn(conn)
  File "/Library/Frameworks/Python.framework/Versions/3.7/lib/python3.7/site-packages/urllib3/connectionpool.py", line 994, in _validate_conn
    conn.connect()
  File "/Library/Frameworks/Python.framework/Versions/3.7/lib/python3.7/site-packages/urllib3/connection.py", line 300, in connect
    conn = self._new_conn()
  File "/Library/Frameworks/Python.framework/Versions/3.7/lib/python3.7/site-packages/urllib3/connection.py", line 169, in _new_conn
    self, "Failed to establish a new connection: %s" % e
urllib3.exceptions.NewConnectionError: <urllib3.connection.VerifiedHTTPSConnection object at 0x102c7b358>: Failed to establish a new connection: [Errno 8] nodename nor servname provided, or not known

During handling of the above exception, another exception occurred:

Traceback (most recent call last):
  File "/Library/Frameworks/Python.framework/Versions/3.7/lib/python3.7/site-packages/requests/adapters.py", line 449, in send
    timeout=timeout
  File "/Library/Frameworks/Python.framework/Versions/3.7/lib/python3.7/site-packages/urllib3/connectionpool.py", line 720, in urlopen
    method, url, error=e, _pool=self, _stacktrace=sys.exc_info()[2]
  File "/Library/Frameworks/Python.framework/Versions/3.7/lib/python3.7/site-packages/urllib3/util/retry.py", line 436, in increment
    raise MaxRetryError(_pool, url, error or ResponseError(cause))
urllib3.exceptions.MaxRetryError: HTTPSConnectionPool(host='weather.com', port=443): Max retries exceeded with url: /weather/hourbyhour/l/Half+Moon+Bay+CA?canonicalCityId=a44ff603208fa7ccf47d5524fe819c587e05a31524b1cb413667b576ac169ea9 (Caused by NewConnectionError('<urllib3.connection.VerifiedHTTPSConnection object at 0x102c7b358>: Failed to establish a new connection: [Errno 8] nodename nor servname provided, or not known'))

During handling of the above exception, another exception occurred:

Traceback (most recent call last):
  File "weather_scrape.py", line 59, in <module>
    main()
  File "weather_scrape.py", line 55, in main
    schedule.run_pending()
  File "/Library/Frameworks/Python.framework/Versions/3.7/lib/python3.7/site-packages/schedule/__init__.py", line 563, in run_pending
    default_scheduler.run_pending()
  File "/Library/Frameworks/Python.framework/Versions/3.7/lib/python3.7/site-packages/schedule/__init__.py", line 94, in run_pending
    self._run_job(job)
  File "/Library/Frameworks/Python.framework/Versions/3.7/lib/python3.7/site-packages/schedule/__init__.py", line 147, in _run_job
    ret = job.run()
  File "/Library/Frameworks/Python.framework/Versions/3.7/lib/python3.7/site-packages/schedule/__init__.py", line 466, in run
    ret = self.job_func()
  File "weather_scrape.py", line 14, in check_weather
    source = requests.get(URL, headers=headers).text
  File "/Library/Frameworks/Python.framework/Versions/3.7/lib/python3.7/site-packages/requests/api.py", line 76, in get
    return request('get', url, params=params, **kwargs)
  File "/Library/Frameworks/Python.framework/Versions/3.7/lib/python3.7/site-packages/requests/api.py", line 61, in request
    return session.request(method=method, url=url, **kwargs)
  File "/Library/Frameworks/Python.framework/Versions/3.7/lib/python3.7/site-packages/requests/sessions.py", line 530, in request
    resp = self.send(prep, **send_kwargs)
  File "/Library/Frameworks/Python.framework/Versions/3.7/lib/python3.7/site-packages/requests/sessions.py", line 643, in send
    r = adapter.send(request, **kwargs)
  File "/Library/Frameworks/Python.framework/Versions/3.7/lib/python3.7/site-packages/requests/adapters.py", line 516, in send
    raise ConnectionError(e, request=request)
requests.exceptions.ConnectionError: HTTPSConnectionPool(host='weather.com', port=443): Max retries exceeded with url: /weather/hourbyhour/l/Half+Moon+Bay+CA?canonicalCityId=a44ff603208fa7ccf47d5524fe819c587e05a31524b1cb413667b576ac169ea9 (Caused by NewConnectionError('<urllib3.connection.VerifiedHTTPSConnection object at 0x102c7b358>: Failed to establish a new connection: [Errno 8] nodename nor servname provided, or not known'))
Traceback (most recent call last):
  File "weather_scrape.py", line 6, in <module>
    import schedule
ModuleNotFoundError: No module named 'schedule'
